2018-12-30 02:21:48,518 INFO: Microblog startup [in /Users/marwanali/Developer/microblog/app/__init__.py:58]
2018-12-30 17:54:02,692 INFO: Microblog startup [in /Users/marwanali/Developer/microblog/app/__init__.py:58]
2018-12-30 17:54:21,435 INFO: Microblog startup [in /Users/marwanali/Developer/microblog/app/__init__.py:58]
2018-12-30 17:57:00,756 INFO: Microblog startup [in /Users/marwanali/Developer/microblog/app/__init__.py:58]
2018-12-30 17:57:59,554 INFO: Microblog startup [in /Users/marwanali/Developer/microblog/app/__init__.py:58]
2018-12-30 22:11:32,771 INFO: Microblog startup [in /Users/marwanali/Developer/microblog/app/__init__.py:58]
2018-12-30 22:13:40,313 INFO: Microblog startup [in /Users/marwanali/Developer/microblog/app/__init__.py:58]
2018-12-30 22:14:30,444 INFO: Microblog startup [in /Users/marwanali/Developer/microblog/app/__init__.py:58]
2018-12-30 22:29:02,180 INFO: Microblog startup [in /Users/marwanali/Developer/microblog/app/__init__.py:58]
2018-12-30 22:30:09,240 INFO: Microblog startup [in /Users/marwanali/Developer/microblog/app/__init__.py:58]
2018-12-30 22:31:28,057 INFO: Microblog startup [in /Users/marwanali/Developer/microblog/app/__init__.py:58]
2018-12-30 22:46:27,411 ERROR: Exception on /follow/other [GET] [in /Users/marwanali/Developer/microblog/venv/lib/python3.6/site-packages/flask/app.py:1761]
Traceback (most recent call last):
  File "/Users/marwanali/Developer/microblog/venv/lib/python3.6/site-packages/flask/app.py", line 2292, in wsgi_app
    response = self.full_dispatch_request()
  File "/Users/marwanali/Developer/microblog/venv/lib/python3.6/site-packages/flask/app.py", line 1815, in full_dispatch_request
    rv = self.handle_user_exception(e)
  File "/Users/marwanali/Developer/microblog/venv/lib/python3.6/site-packages/flask/app.py", line 1718, in handle_user_exception
    reraise(exc_type, exc_value, tb)
  File "/Users/marwanali/Developer/microblog/venv/lib/python3.6/site-packages/flask/_compat.py", line 35, in reraise
    raise value
  File "/Users/marwanali/Developer/microblog/venv/lib/python3.6/site-packages/flask/app.py", line 1813, in full_dispatch_request
    rv = self.dispatch_request()
  File "/Users/marwanali/Developer/microblog/venv/lib/python3.6/site-packages/flask/app.py", line 1799, in dispatch_request
    return self.view_functions[rule.endpoint](**req.view_args)
  File "/Users/marwanali/Developer/microblog/venv/lib/python3.6/site-packages/flask_login/utils.py", line 261, in decorated_view
    return func(*args, **kwargs)
  File "/Users/marwanali/Developer/microblog/app/routes.py", line 125, in follow
    current_user.follow(username)
  File "/Users/marwanali/Developer/microblog/app/models.py", line 56, in follow
    if not self.is_following(user):
  File "/Users/marwanali/Developer/microblog/app/models.py", line 64, in is_following
    following = self.followed.filter(followers.c.followed_id == user.id).count() > 0
AttributeError: 'str' object has no attribute 'id'
2018-12-30 22:50:48,249 ERROR: Exception on /follow/other [GET] [in /Users/marwanali/Developer/microblog/venv/lib/python3.6/site-packages/flask/app.py:1761]
Traceback (most recent call last):
  File "/Users/marwanali/Developer/microblog/venv/lib/python3.6/site-packages/flask/app.py", line 2292, in wsgi_app
    response = self.full_dispatch_request()
  File "/Users/marwanali/Developer/microblog/venv/lib/python3.6/site-packages/flask/app.py", line 1815, in full_dispatch_request
    rv = self.handle_user_exception(e)
  File "/Users/marwanali/Developer/microblog/venv/lib/python3.6/site-packages/flask/app.py", line 1718, in handle_user_exception
    reraise(exc_type, exc_value, tb)
  File "/Users/marwanali/Developer/microblog/venv/lib/python3.6/site-packages/flask/_compat.py", line 35, in reraise
    raise value
  File "/Users/marwanali/Developer/microblog/venv/lib/python3.6/site-packages/flask/app.py", line 1813, in full_dispatch_request
    rv = self.dispatch_request()
  File "/Users/marwanali/Developer/microblog/venv/lib/python3.6/site-packages/flask/app.py", line 1799, in dispatch_request
    return self.view_functions[rule.endpoint](**req.view_args)
  File "/Users/marwanali/Developer/microblog/venv/lib/python3.6/site-packages/flask_login/utils.py", line 261, in decorated_view
    return func(*args, **kwargs)
  File "/Users/marwanali/Developer/microblog/app/routes.py", line 125, in follow
    current_user.follow(username)
  File "/Users/marwanali/Developer/microblog/app/models.py", line 56, in follow
    if not self.is_following(user):
  File "/Users/marwanali/Developer/microblog/app/models.py", line 64, in is_following
    following = self.followed.filter(followers.c.followed_id == user.id).count() > 0
AttributeError: 'str' object has no attribute 'id'
2018-12-30 22:51:39,090 ERROR: Exception on /follow/other [GET] [in /Users/marwanali/Developer/microblog/venv/lib/python3.6/site-packages/flask/app.py:1761]
Traceback (most recent call last):
  File "/Users/marwanali/Developer/microblog/venv/lib/python3.6/site-packages/flask/app.py", line 2292, in wsgi_app
    response = self.full_dispatch_request()
  File "/Users/marwanali/Developer/microblog/venv/lib/python3.6/site-packages/flask/app.py", line 1815, in full_dispatch_request
    rv = self.handle_user_exception(e)
  File "/Users/marwanali/Developer/microblog/venv/lib/python3.6/site-packages/flask/app.py", line 1718, in handle_user_exception
    reraise(exc_type, exc_value, tb)
  File "/Users/marwanali/Developer/microblog/venv/lib/python3.6/site-packages/flask/_compat.py", line 35, in reraise
    raise value
  File "/Users/marwanali/Developer/microblog/venv/lib/python3.6/site-packages/flask/app.py", line 1813, in full_dispatch_request
    rv = self.dispatch_request()
  File "/Users/marwanali/Developer/microblog/venv/lib/python3.6/site-packages/flask/app.py", line 1799, in dispatch_request
    return self.view_functions[rule.endpoint](**req.view_args)
  File "/Users/marwanali/Developer/microblog/venv/lib/python3.6/site-packages/flask_login/utils.py", line 261, in decorated_view
    return func(*args, **kwargs)
  File "/Users/marwanali/Developer/microblog/app/routes.py", line 125, in follow
    current_user.follow(other_user)
  File "/Users/marwanali/Developer/microblog/app/models.py", line 56, in follow
    if not self.is_following(user):
  File "/Users/marwanali/Developer/microblog/app/models.py", line 64, in is_following
    following = self.followed.filter(followers.c.followed_id == user.id).count() > 0
AttributeError: 'str' object has no attribute 'id'
2018-12-30 22:51:43,855 ERROR: Exception on /follow/other [GET] [in /Users/marwanali/Developer/microblog/venv/lib/python3.6/site-packages/flask/app.py:1761]
Traceback (most recent call last):
  File "/Users/marwanali/Developer/microblog/venv/lib/python3.6/site-packages/flask/app.py", line 2292, in wsgi_app
    response = self.full_dispatch_request()
  File "/Users/marwanali/Developer/microblog/venv/lib/python3.6/site-packages/flask/app.py", line 1815, in full_dispatch_request
    rv = self.handle_user_exception(e)
  File "/Users/marwanali/Developer/microblog/venv/lib/python3.6/site-packages/flask/app.py", line 1718, in handle_user_exception
    reraise(exc_type, exc_value, tb)
  File "/Users/marwanali/Developer/microblog/venv/lib/python3.6/site-packages/flask/_compat.py", line 35, in reraise
    raise value
  File "/Users/marwanali/Developer/microblog/venv/lib/python3.6/site-packages/flask/app.py", line 1813, in full_dispatch_request
    rv = self.dispatch_request()
  File "/Users/marwanali/Developer/microblog/venv/lib/python3.6/site-packages/flask/app.py", line 1799, in dispatch_request
    return self.view_functions[rule.endpoint](**req.view_args)
  File "/Users/marwanali/Developer/microblog/venv/lib/python3.6/site-packages/flask_login/utils.py", line 261, in decorated_view
    return func(*args, **kwargs)
  File "/Users/marwanali/Developer/microblog/app/routes.py", line 125, in follow
    current_user.follow(other_user)
  File "/Users/marwanali/Developer/microblog/app/models.py", line 56, in follow
    if not self.is_following(user):
  File "/Users/marwanali/Developer/microblog/app/models.py", line 64, in is_following
    following = self.followed.filter(followers.c.followed_id == user.id).count() > 0
AttributeError: 'str' object has no attribute 'id'
2018-12-30 22:51:52,962 INFO: Microblog startup [in /Users/marwanali/Developer/microblog/app/__init__.py:58]
2019-01-02 11:34:47,949 INFO: Microblog startup [in /Users/marwanali/Developer/microblog/app/__init__.py:58]
