2019-01-03 06:22:39,414 ERROR: Exception on /reset_password_request [POST] [in /Users/marwanali/Developer/microblog/venv/lib/python3.6/site-packages/flask/app.py:1761]
Traceback (most recent call last):
  File "/Users/marwanali/Developer/microblog/venv/lib/python3.6/site-packages/flask_mail.py", line 492, in send
    message.send(connection)
  File "/Users/marwanali/Developer/microblog/venv/lib/python3.6/site-packages/flask_mail.py", line 427, in send
    connection.send(self)
  File "/Users/marwanali/Developer/microblog/venv/lib/python3.6/site-packages/flask_mail.py", line 192, in send
    message.rcpt_options)
  File "/usr/local/Cellar/python/3.6.4_3/Frameworks/Python.framework/Versions/3.6/lib/python3.6/smtplib.py", line 852, in sendmail
    self.ehlo_or_helo_if_needed()
  File "/usr/local/Cellar/python/3.6.4_3/Frameworks/Python.framework/Versions/3.6/lib/python3.6/smtplib.py", line 600, in ehlo_or_helo_if_needed
    if not (200 <= self.ehlo()[0] <= 299):
  File "/usr/local/Cellar/python/3.6.4_3/Frameworks/Python.framework/Versions/3.6/lib/python3.6/smtplib.py", line 440, in ehlo
    self.putcmd(self.ehlo_msg, name or self.local_hostname)
  File "/usr/local/Cellar/python/3.6.4_3/Frameworks/Python.framework/Versions/3.6/lib/python3.6/smtplib.py", line 367, in putcmd
    self.send(str)
  File "/usr/local/Cellar/python/3.6.4_3/Frameworks/Python.framework/Versions/3.6/lib/python3.6/smtplib.py", line 359, in send
    raise SMTPServerDisconnected('please run connect() first')
smtplib.SMTPServerDisconnected: please run connect() first

During handling of the above exception, another exception occurred:

Traceback (most recent call last):
  File "/Users/marwanali/Developer/microblog/venv/lib/python3.6/site-packages/flask/app.py", line 2292, in wsgi_app
    response = self.full_dispatch_request()
  File "/Users/marwanali/Developer/microblog/venv/lib/python3.6/site-packages/flask/app.py", line 1815, in full_dispatch_request
    rv = self.handle_user_exception(e)
  File "/Users/marwanali/Developer/microblog/venv/lib/python3.6/site-packages/flask/app.py", line 1718, in handle_user_exception
    reraise(exc_type, exc_value, tb)
  File "/Users/marwanali/Developer/microblog/venv/lib/python3.6/site-packages/flask/_compat.py", line 35, in reraise
    raise value
  File "/Users/marwanali/Developer/microblog/venv/lib/python3.6/site-packages/flask/app.py", line 1813, in full_dispatch_request
    rv = self.dispatch_request()
  File "/Users/marwanali/Developer/microblog/venv/lib/python3.6/site-packages/flask/app.py", line 1799, in dispatch_request
    return self.view_functions[rule.endpoint](**req.view_args)
  File "/Users/marwanali/Developer/microblog/app/routes.py", line 210, in reset_password_request
    send_password_reset_email(user)
  File "/Users/marwanali/Developer/microblog/app/email.py", line 20, in send_password_reset_email
    html_body=render_template('email/reset_password.html', user=user, token=token)
  File "/Users/marwanali/Developer/microblog/app/email.py", line 10, in send_email
    mail.send(msg)
  File "/Users/marwanali/Developer/microblog/venv/lib/python3.6/site-packages/flask_mail.py", line 492, in send
    message.send(connection)
  File "/Users/marwanali/Developer/microblog/venv/lib/python3.6/site-packages/flask_mail.py", line 152, in __exit__
    self.host.quit()
  File "/usr/local/Cellar/python/3.6.4_3/Frameworks/Python.framework/Versions/3.6/lib/python3.6/smtplib.py", line 983, in quit
    res = self.docmd("quit")
  File "/usr/local/Cellar/python/3.6.4_3/Frameworks/Python.framework/Versions/3.6/lib/python3.6/smtplib.py", line 420, in docmd
    self.putcmd(cmd, args)
  File "/usr/local/Cellar/python/3.6.4_3/Frameworks/Python.framework/Versions/3.6/lib/python3.6/smtplib.py", line 367, in putcmd
    self.send(str)
  File "/usr/local/Cellar/python/3.6.4_3/Frameworks/Python.framework/Versions/3.6/lib/python3.6/smtplib.py", line 359, in send
    raise SMTPServerDisconnected('please run connect() first')
smtplib.SMTPServerDisconnected: please run connect() first
2019-01-03 06:32:44,995 INFO: Microblog startup [in /Users/marwanali/Developer/microblog/app/__init__.py:64]
2019-01-03 06:34:00,820 ERROR: Exception on /user/marwan [GET] [in /Users/marwanali/Developer/microblog/venv/lib/python3.6/site-packages/flask/app.py:1761]
Traceback (most recent call last):
  File "/Users/marwanali/Developer/microblog/venv/lib/python3.6/site-packages/flask/app.py", line 2292, in wsgi_app
    response = self.full_dispatch_request()
  File "/Users/marwanali/Developer/microblog/venv/lib/python3.6/site-packages/flask/app.py", line 1815, in full_dispatch_request
    rv = self.handle_user_exception(e)
  File "/Users/marwanali/Developer/microblog/venv/lib/python3.6/site-packages/flask/app.py", line 1718, in handle_user_exception
    reraise(exc_type, exc_value, tb)
  File "/Users/marwanali/Developer/microblog/venv/lib/python3.6/site-packages/flask/_compat.py", line 35, in reraise
    raise value
  File "/Users/marwanali/Developer/microblog/venv/lib/python3.6/site-packages/flask/app.py", line 1813, in full_dispatch_request
    rv = self.dispatch_request()
  File "/Users/marwanali/Developer/microblog/venv/lib/python3.6/site-packages/flask/app.py", line 1799, in dispatch_request
    return self.view_functions[rule.endpoint](**req.view_args)
  File "/Users/marwanali/Developer/microblog/venv/lib/python3.6/site-packages/flask_login/utils.py", line 261, in decorated_view
    return func(*args, **kwargs)
  File "/Users/marwanali/Developer/microblog/app/routes.py", line 118, in user
    return render_template('user.html', user=user, posts=posts.items, next_url=next_url, prev_url=prev_url)
  File "/Users/marwanali/Developer/microblog/venv/lib/python3.6/site-packages/flask/templating.py", line 135, in render_template
    context, ctx.app)
  File "/Users/marwanali/Developer/microblog/venv/lib/python3.6/site-packages/flask/templating.py", line 117, in _render
    rv = template.render(context)
  File "/Users/marwanali/Developer/microblog/venv/lib/python3.6/site-packages/jinja2/asyncsupport.py", line 76, in render
    return original_render(self, *args, **kwargs)
  File "/Users/marwanali/Developer/microblog/venv/lib/python3.6/site-packages/jinja2/environment.py", line 1008, in render
    return self.environment.handle_exception(exc_info, True)
  File "/Users/marwanali/Developer/microblog/venv/lib/python3.6/site-packages/jinja2/environment.py", line 780, in handle_exception
    reraise(exc_type, exc_value, tb)
  File "/Users/marwanali/Developer/microblog/venv/lib/python3.6/site-packages/jinja2/_compat.py", line 37, in reraise
    raise value.with_traceback(tb)
  File "/Users/marwanali/Developer/microblog/app/templates/user.html", line 1, in top-level template code
    {% extends "base.html" %}
  File "/Users/marwanali/Developer/microblog/app/templates/base.html", line 1, in top-level template code
    {% extends 'bootstrap/base.html' %}
  File "/Users/marwanali/Developer/microblog/venv/lib/python3.6/site-packages/flask_bootstrap/templates/bootstrap/base.html", line 1, in top-level template code
    {% block doc -%}
  File "/Users/marwanali/Developer/microblog/venv/lib/python3.6/site-packages/flask_bootstrap/templates/bootstrap/base.html", line 4, in block "doc"
    {%- block html %}
  File "/Users/marwanali/Developer/microblog/venv/lib/python3.6/site-packages/flask_bootstrap/templates/bootstrap/base.html", line 20, in block "html"
    {% block body -%}
  File "/Users/marwanali/Developer/microblog/venv/lib/python3.6/site-packages/flask_bootstrap/templates/bootstrap/base.html", line 23, in block "body"
    {% block content -%}
  File "/Users/marwanali/Developer/microblog/app/templates/base.html", line 48, in block "content"
    {% block app_content %}{% endblock %}
  File "/Users/marwanali/Developer/microblog/app/templates/user.html", line 6, in block "app_content"
    <td width="256px"><img src="{{ user.avatar(256) }}"></td>
jinja2.exceptions.UndefinedError: 'app.models.User object' has no attribute 'avatar'
